Workbook

Sheet Readme
B1: # INTRODUCTION
C2: The Management Spreadsheet (MSS) is a Software built in LibreOffice and saved as Excel xlsx file.
C3: It is considered a Tool and integral part of the *Management Framework* as discused in the note MGT: Legend.
C4: This software can be used on a standalone basis but its strength is in use with the MGT: xxx notes.
C5: The software can be found wihtin the management file structure in the following location: ~/mgt/mgt.xlsx
C7: MSS is the same for perso and work context, and the master of the functionality is maintained in the perso context.
C8: As per the license, see below, the software can be used freely, but it is stressed here that that free distribution only pertains to concepts and functionality.
C9: In other words, data collected in the spreadsheet is confidential for the context used, and even specific to the Venture.
C11: In order to use this file efficiently the key concepts of the Management Framework need to be understood.
C12: These concepts are discussed in the note MGT: Legend. The implementation of the concepts through Tools is discussed in note MGT: 99.Tools.
C14: All sheets in MSS are functionally the same in perso and work context with one exception (see further below).
C15: This in turn means they seek to collect the same data types and to calculate the same values.
C17: Sheets have tab colors that indicate the type of sheet they are, they are explained below in [# SHEETS].
... C26: Details are provided below under [# COLUMNS]
B29: # LICENSE
C30: The license of this software is as per [MGT: Legend # LICENSE]. It is repeated here.
C31: MSS is a Tool for the implementation of the Management Framework based on [MGT: Legend # PROFILE] and [MGT: 99.Tools ## MSS].
C33: Copyright (c) 2022 Sander Elzinga, sander.elzinga@gmail.com
C35: This program is free software: you can redistribute it and/or modify
C36: it under the terms of the GNU General Public License as published by
C37: the Free Software Foundation, either version 3 of the License, or
C38: (at your option) any later version.
C40: This program is distributed in the hope that it will be useful,
C41: but WITHOUT ANY WARRANTY; without even the implied warranty of
C42: MERCHANTABILITY or FITNESS FOR A PARTICULAR PURPOSE. See the
C43: GNU General Public License for more details.
C45: You should have received a copy of the GNU General Public License
... C50: *) Data is the data entered in addition to the formulas, static data, headers, and in addition of the data already provided in the master file.
B53: # SHEETS
B54: ## Overview
C55: Sheets are aligned to specific parts of the [MGT: 99.Tools ## RPT] and have therefore specific tab colours.
C56: The list of sheets are provided below with an explanation.
C57: Most sheets have a first Row that explains for each column in the Row what the undelrying data is.
C58: This makes each sheet self explanatory because it suffices to read the details in the first row.
C60: Readme | E60: This sheet. It explains what the MSS file does.
C61: PT_xxx | E61: Sheet names starting with PT_ is a Pivot Table report for a specific purpose, there can be many sheets.
C62: M0 | E62: Mangerial 7 nr 0: Management
C63: M1 | E63: Mangerial 7 nr 1: Revenue
C64: M2 | E64: Mangerial 7 nr 2: Cost
C65: M3 | E65: Mangerial 7 nr 3: Risk
...

Sheet PT_templ
A1: Sort | B1: - all -
A2: Item Type | B2: - all -
A3: Lvl | B3: - all -
A5: Self | B5: Hold Date | C5: Self+1 Pty | D5: Key | E5: Sum - Effort
A6: (empty) | B6: (empty) | C6: 0 | D6: (empty) | E6: 0
A7: VNT | B7: (empty) | C7: 0 | D7: VNT | E7: 1
A8: Action Some Action for the Study | B8: (empty) | C8: 45658 | D8: Action Some Action for the Study | E8: 0
A9: Chg GoalDMM | B9: (empty) | C9: 0 | D9: Chg GoalDMM | E9: 0
A10: Chg GoalEMM | B10: (empty) | C10: 0 | D10: Chg GoalEMM | E10: 0
A11: ProjectSome Study Project for sub-cat 1 | B11: (empty) | C11: 0 | D11: ProjectSome Study Project for sub-cat 1 | E11: 0
A12: ProjectSome Study Project for sub-cat 2 | B12: (empty) | C12: 0 | D12: ProjectSome Study Project for sub-cat 2 | E12: 0
A13: Stream Some Stream of the project | B13: (empty) | C13: 45658 | D13: Stream Some Stream of the project | E13: 0
A14: Total Result | E14: 1

Sheet Tracker
BW1: x
BW2: x
BW3: x
A4: =A3 -> 0 | B4: =B3 -> 0 | C4: =C3 -> 0 | D4: =D3 -> 0 | E4: =E3 -> 0 | F4: =F3 -> 0 | G4: =G3 -> 0 | H4: =H3 -> 0 | ... R4: =R3 -> 0 | Z4: =Z3 -> 0 | AB4: =AB3 -> 0 | AC4: =AC3 -> 0 | AD4: =AD3 -> 0 | AE4: =AE3 -> 0 | AF4: =AF3 -> 0 | AG4: =AG3 -> 0 | AH4: =AH3 -> 0 | AI4: =AI3 -> 0 | ... AK4: =AK3 -> 0 | BW4: =BW3 -> x
BW5: x
BW6: x
BW7: x
BW15: x
BW16: x
BW17: x
BW18: x
BW19: x
BW20: x
A21: =TODAY() -> 46321 | B21: Calculated. First Note of Column = Notes. | C21: Calculated. Last Note -f Column = Notes. | D21: Calculated. Date of First NoTe from Column = First Note. | E21: Calculated. Date of Last Note from Column = Last Note. | F21: Calculated. Date of the Last Note or epoch based on Col = Notes. | G21: Calcualted. Time between Last Date and Start Date. | H21: Calculated. Nr Tasks in Status indicated by name of this Column. The IF() is to account for the fact that typing anything at the start of a cell is not preceded the <ENTER> Character CHAR(10). | I21: Calculated. Nr Tasks in Status indicated by name of this Column. The IF() is to account for the fact that typing anything at the start of a cell is not preceded the <ENTER> Character CHAR(10). | J21: Calculated. Nr Tasks in Status indicated by name of this Column. The IF() is to account for the fact that typing anything at the start of a cell is not preceded the <ENTER> Character CHAR(10). | K21: Calculated. Nr Tasks in Status indicated by name of this Column. The IF() is to account for the fact that typing anything at the start of a cell is not preceded the <ENTER> Character CHAR(10). | L21: Calculated. Nr Tasks in Status indicated by name of this Column. The IF() is to account for the fact that typing anything at the start of a cell is not preceded the <ENTER> Character CHAR(10). | M21: Calaculated. Sum of all Tasks in Tasks. | N21: Calcualted. Whether the Last Date was within X weeks of the Monday of the week of the date in cell $D$2. | O21: Calculated. Assures Tracking Type = Management is at the top, then Routines, then Projects that are Roadmap items, then Projects and then the rest of the entries. | P21: Calculated. Whether the Jounral entry is reportable based on whether the Last Date is newer than the monday X weeks ago, with X determined in Cell $D$2. | Q21: Optional. Can force the reporting of a Journal Entry if the defaulting rules would (not) report an entry. | R21: Optional. Tag the entry for specific filtering. The value can be freely chosen. It is possible to have multiple comma-separated values. This column is an incredibly powerful feature of the entire sheet. | S21: Whom For Level 1. Mandatory. The Beneficiery. The Activity for which this is performed. The Default = the entire Venture VNT. | X21: Optional: This column has a drop-down which is based on the value in the column to the left i.e. Sub-Goal depends on Goal. | Z21: Mandatory. In theory several options possible, but choose only “Routine”. | AB21: Mandatory. 6W = What: part 1 of Name. Name is preferably unique within the Tracking Type and should start with a Verb. Verbs are an indication of targeted Result, see [MGT: 99. Tools ## Objective Definition]: - Assist: somebody in execution of their Process - Attend: prepare and attend a meeting - Build: something new from scratch - Complete: something started elsewhere/prior - Create: same as Build - Define: a Target/expected Result, next Build/Create - Deploy: as new something existing elsewhere - Expand: something existing by adding to it - Improve: something existing by automation etc. - Increase: something existing by a numeric value - Learn: something that may become important later on - Maintain: something existing at current level - Meet: someone on regular or ad-hoc basis - Perform: one or more specific Processes - Prepare: a deliverable for completion elsewhere - Process: take in a request and deliver Result - React to: a situation with specific measures - Report to: Staff, Manager, Committee via mail - Resolve: Problems - Review: Result vs Target + assess if change needed - Rewrite: an existing document | AC21: Optional. 6W = How: Details of how the Routine is achieved. | AD21: Mandatory. Notes drive two columns: Start Date and Last Date. Format for each line: dd-mm-yy: xxx in which dd, mm and yy are day, month and year and xxx is free text. | AE21: Optional. Tasks with individual Status. Multiple entries are possible. In combination with Column = Updated this column helps in Reporting. Items follow the Objective Notation as per [MGT: 99.Tools ## Objective Notation] i.e. Status Description (start:end:complete) {who} [ref] NB: Goal end Effort are not relevant for this Column. Used in Formulas. | AF21: Calculated. Nr non-completed Tasks. | AG21: Calculated. Nr Tasks non-completed Tasks over total nr Tasks as %. | AH21: Mandatory. The frequency type of the Routine, based on a drop-down list maintained in Sheet=Static. | AI21: Mandatory. The number of times the Routine is done throughout a year. This is partially linked to Period (label): Day -> 260 (without holidays), 220 (with holidays) Week -> 52 (without holidays), 48 (with full week holidays) Month -> 12 Quarterly -> 4 Semi-annually -> 2 Annually -> 1 Ad-hoc -> this is determined by the user depending on expetations based on past or current information | AJ21: Mandatory. THe amount of hours worked on each time the Routine is performed. | AK21: Calculated. Total nr of 8-hour days the ROutine takes. | AL21: When | AM21: When | AN21: When | AO21: When | AP21: When | AQ21: Custom Field 1 | AR21: Custom Field 2 | AS21: Custom Field 3 | AT21: Custom Field 4 | AU21: Custom Field 5 | AV21: Custom Field 6 | AW21: Custom Field 7 | AX21: Custom Field 8 | AY21: Custom Field 9 | AZ21: Custom Field 10 | BA21: Custom Field 11 | BB21: Custom Field 12 | BC21: Custom Field 13 | BD21: Custom Field 14 | BE21: Custom Field 15 | BF21: Custom Field 16 | BG21: Custom Field 17 | BH21: Custom Field 18 | BI21: Custom Field 19 | BJ21: Custom Field 20 | BW21: Last Column. Contains value = “X”.
F22: 1 | AG22: ## This indicates that Today is in the Month below → | BK22: =IF(AND($A$21>BK23,$A$21<(DATE(YEAR(BK23),MONTH(BK23),DAY(EOMONTH(DATE(YEAR(BK23),MONTH(BK23),1),0))))),1,0) -> 0 | BL22: =IF(AND($A$21>BL23,$A$21<(DATE(YEAR(BL23),MONTH(BL23),DAY(EOMONTH(DATE(YEAR(BL23),MONTH(BL23),1),0))))),1,0) -> 0 | BM22: =IF(AND($A$21>BM23,$A$21<(DATE(YEAR(BM23),MONTH(BM23),DAY(EOMONTH(DATE(YEAR(BM23),MONTH(BM23),1),0))))),1,0) -> 0 | BN22: =IF(AND($A$21>BN23,$A$21<(DATE(YEAR(BN23),MONTH(BN23),DAY(EOMONTH(DATE(YEAR(BN23),MONTH(BN23),1),0))))),1,0) -> 0 | BO22: =IF(AND($A$21>BO23,$A$21<(DATE(YEAR(BO23),MONTH(BO23),DAY(EOMONTH(DATE(YEAR(BO23),MONTH(BO23),1),0))))),1,0) -> 0 | BP22: =IF(AND($A$21>BP23,$A$21<(DATE(YEAR(BP23),MONTH(BP23),DAY(EOMONTH(DATE(YEAR(BP23),MONTH(BP23),1),0))))),1,0) -> 0 | BQ22: =IF(AND($A$21>BQ23,$A$21<(DATE(YEAR(BQ23),MONTH(BQ23),DAY(EOMONTH(DATE(YEAR(BQ23),MONTH(BQ23),1),0))))),1,0) -> 0 | BR22: =IF(AND($A$21>BR23,$A$21<(DATE(YEAR(BR23),MONTH(BR23),DAY(EOMONTH(DATE(YEAR(BR23),MONTH(BR23),1),0))))),1,0) -> 0 | ... BV22: =IF(AND($A$21>BV23,$A$21<(DATE(YEAR(BV23),MONTH(BV23),DAY(EOMONTH(DATE(YEAR(BV23),MONTH(BV23),1),0))))),1,0) -> 0
A23: A | B23: First Note | C23: Last Note | D23: First Note Date | E23: Last Note Date | F23: Last Date | G23: Duration | H23: Tasks Open | I23: Tasks Started | J23: Tasks Pending | K23: Tasks Urgent | L23: Tasks Done | M23: Tasks Total | N23: Last wk? | O23: Sort | P23: Rep ? | Q23: Force Rep? | R23: Tag | S23: Whom for lvl1 | T23: Whom for lvl2 | U23: Whom By Lvl1 | V23: Whom By Lvl2 | W23: Goal | X23: Sub-Goal | Y23: Initiative | Z23: Planning Type | AA23: Status | AB23: Name | AC23: Details: | AD23: Notes | AE23: Tasks | AF23: Tasks Left | AG23: Task Progress | AH23: Period (label) | AI23: Period (count) | AJ23: Effort / count (hr) | AK23: Effort / yr (days) | AL23: Start Date | AM23: End Date | AN23: Hold Date | AO23: Complete Date | AP23: Effort / project (days) | AQ23: Custom Field 1 | AR23: Custom Field 2 | AS23: Custom Field 3 | AT23: Custom Field 4 | AU23: Custom Field 5 | AV23: Custom Field 6 | AW23: Custom Field 7 | AX23: Custom Field 8 | AY23: Custom Field 9 | AZ23: Custom Field 10 | BA23: Custom Field 11 | BB23: Custom Field 12 | BC23: Custom Field 13 | BD23: Custom Field 14 | BE23: Custom Field 15 | BF23: Custom Field 16 | BG23: Custom Field 17 | BH23: Custom Field 18 | BI23: Custom Field 19 | BJ23: Custom Field 20 | BK23: 45658 | BL23: 45689 | BM23: 45717 | BN23: 45748 | BO23: 45778 | BP23: 45809 | BQ23: 45839 | BR23: 45870 | BS23: 45901 | BT23: 45931 | BU23: 45962 | BV23: 45992 | BW23: Z
A24: =A23 -> A | B24: =B23 -> First Note | C24: =C23 -> Last Note | D24: =D23 -> First Note Date | E24: =E23 -> Last Note Date | F24: =F23 -> Last Date | G24: =G23 -> Duration | H24: =H23 -> Tasks Open | ... Q24: =Q23 -> Force Rep? | S24: =S23 -> Whom for lvl1 | T24: =T23 -> Whom for lvl2 | U24: =U23 -> Whom By Lvl1 | V24: =V23 -> Whom By Lvl2 | W24: =W23 -> Goal | X24: =X23 -> Sub-Goal | Y24: =Y23 -> Initiative | Z24: =Z23 -> Planning Type | ... BK24: =BK23 -> 45658 | BW24: =BW23 -> Z
B25: =IF(AD25="","",IF(ISERROR(FIND(CHAR(10),AD25,1)),AD25,LEFT(AD25,FIND(CHAR(10),AD25,1)))) -> 03-01-22: init | C25: =IF(AD25="","",IFERROR(RIGHT(AD25,LEN(AD25)-FIND("@@@",SUBSTITUTE(AD25,CHAR(10),"@@@",LEN(AD25)-LEN(SUBSTITUTE(AD25,CHAR(10),""))),1)),AD25)) -> 03-01-22: init | D25: =IFERROR(DATE(("20"&MID(B25,7,2))*1,MID(B25,4,2)*1,MID(B25,1,2)*1),"") -> 44564 | E25: =IFERROR(DATE(("20"&MID(C25,7,2))*1,MID(C25,4,2)*1,MID(C25,1,2)*1),"") -> 44564 | F25: =MAX(D25,IF(E25="none",D25,E25)) -> 44564 | G25: =IFERROR(DAYS360(D25,F25),0) -> 0 | H25: =((LEN($AE25)-LEN(SUBSTITUTE($AE25,CHAR(10)&". ","")))/3)+IF(LEFT(TRIM($AE25),2)=". ",1,0) -> 0 | I25: =((LEN($AE25)-LEN(SUBSTITUTE($AE25,CHAR(10)&"/ ","")))/3)+IF(LEFT(TRIM($AE25),2)="/ ",1,0) -> 0 | J25: =((LEN($AE25)-LEN(SUBSTITUTE($AE25,CHAR(10)&"~ ","")))/3)+IF(LEFT(TRIM($AE25),2)="~ ",1,0) -> 0 | K25: =((LEN($AE25)-LEN(SUBSTITUTE($AE25,CHAR(10)&"! ","")))/3)+IF(LEFT(TRIM($AE25),2)="! ",1,0) -> 0 | L25: =((LEN($AE25)-LEN(SUBSTITUTE($AE25,CHAR(10)&"x ","")))/3)+IF(LEFT(TRIM($AE25),2)="x ",1,0) -> 0 | M25: =SUM(H25:L25) -> 0 | N25: =IF(F25>(($A$21-WEEKDAY($A$21,2))-7*$F$22),"Y","N") -> N | O25: =IF(AB25=""," - ZZZ"," - "&X25&Y25&AB25) -> - 00.managementGeneral Management00.Maintain Management | P25: =IF(AB25="","",(IF(OR(Q25="Y",Q25="N"),Q25,IF(N25="Y","Y","N")))) -> N | Q25: N | S25: VNT | T25: _all | U25: n/a | V25: Sander | W25: mgt | X25: 00.management | Y25: General Management | Z25: Routine | AA25: Started | AB25: 00.Maintain Management | AC25: Details: # INTRODUCTION Details of this management item are in the Management Framework. | AD25: 03-01-22: init | AE25: ## Generic Routines & Maintain MSS [this file] & Maintain Management Framework [the local implementation of the public domain version of the Management Framework] & Maintain Management Approach [## Management Approach] ________________________________________ ## Management Approach ## _END | AF25: =IF(AB25="","",SUM(H25:K25)) -> 0 | AG25: =IF(AB25="","",IF(M25<>0,(I25*0.5+L25)/M25,1)) -> 1 | AH25: Ad-hoc | AK25: =IF(AB25="","",AI25*AJ25/8) -> 0 | BW25: z
B26: =IF(AD26="","",IF(ISERROR(FIND(CHAR(10),AD26,1)),AD26,LEFT(AD26,FIND(CHAR(10),AD26,1)))) -> 03-01-22: init | C26: =IF(AD26="","",IFERROR(RIGHT(AD26,LEN(AD26)-FIND("@@@",SUBSTITUTE(AD26,CHAR(10),"@@@",LEN(AD26)-LEN(SUBSTITUTE(AD26,CHAR(10),""))),1)),AD26)) -> 03-01-22: init | D26: =IFERROR(DATE(("20"&MID(B26,7,2))*1,MID(B26,4,2)*1,MID(B26,1,2)*1),"") -> 44564 | E26: =IFERROR(DATE(("20"&MID(C26,7,2))*1,MID(C26,4,2)*1,MID(C26,1,2)*1),"") -> 44564 | F26: =MAX(D26,IF(E26="none",D26,E26)) -> 44564 | G26: =IFERROR(DAYS360(D26,F26),0) -> 0 | H26: =((LEN($AE26)-LEN(SUBSTITUTE($AE26,CHAR(10)&". ","")))/3)+IF(LEFT(TRIM($AE26),2)=". ",1,0) -> 0 | I26: =((LEN($AE26)-LEN(SUBSTITUTE($AE26,CHAR(10)&"/ ","")))/3)+IF(LEFT(TRIM($AE26),2)="/ ",1,0) -> 0 | J26: =((LEN($AE26)-LEN(SUBSTITUTE($AE26,CHAR(10)&"~ ","")))/3)+IF(LEFT(TRIM($AE26),2)="~ ",1,0) -> 0 | K26: =((LEN($AE26)-LEN(SUBSTITUTE($AE26,CHAR(10)&"! ","")))/3)+IF(LEFT(TRIM($AE26),2)="! ",1,0) -> 0 | L26: =((LEN($AE26)-LEN(SUBSTITUTE($AE26,CHAR(10)&"x ","")))/3)+IF(LEFT(TRIM($AE26),2)="x ",1,0) -> 0 | M26: =SUM(H26:L26) -> 0 | N26: =IF(F26>(($A$21-WEEKDAY($A$21,2))-7*$F$22),"Y","N") -> N | O26: =IF(AB26=""," - ZZZ"," - "&X26&Y26&AB26) -> - 01.planningGeneral Management00.Maintain Planning | P26: =IF(AB26="","",(IF(OR(Q26="Y",Q26="N"),Q26,IF(N26="Y","Y","N")))) -> N | Q26: N | S26: VNT | T26: _all | U26: n/a | V26: Sander | W26: mgt | X26: 01.planning | Y26: General Management | Z26: Routine | AA26: Started | AB26: 00.Maintain Planning | AC26: Details: # INTRODUCTION Details of this management item are in the Management Framework. | AD26: 03-01-22: init | AE26: ## Generic Routines & 01.Maintain Business Model [## Business Model] & 02.Maintain Purpose [## Purpose] & 03.Maintan Vision [## Vision] & 04.Maintain Mission [## Mission] & 05.Maintain Values [## Values] & 06.Maintain Bylaws [## Bylaws] & 07.Maintain SWOT [## SWOT] & 08.Maintain Goals [## Goals] & 09.Maintain Objectives [## Objectives] & 10.Maintain Tasks [## Tasks] & 11.Maintain Benchmarks [## Benchmarks] & 12.Maintain Strategic Plan [## Strategic Plan] & 13.Maintain Tactical Plan [## Tactical Plan] & 14. Maintain Operational Plan [## Operational Plan] & 15.Maintain Intel [## Intel] ________________________________________ ## Business Model ________________________________________ ## Purpose ________________________________________ ## Vision ________________________________________ ## Mission ________________________________________ ## Values ________________________________________ ## Bylaws ________________________________________ ## SWOT ________________________________________ ## Goals ________________________________________ ## Objectives ________________________________________ ## Tasks ________________________________________ ## Benchmarks ________________________________________ ## Strategic Plan ________________________________________ ## Tactical Plan ________________________________________ ## Operational Plan ________________________________________ ## Intel ## _END | AF26: =IF(AB26="","",SUM(H26:K26)) -> 0 | AG26: =IF(AB26="","",IF(M26<>0,(I26*0.5+L26)/M26,1)) -> 1 | AH26: Ad-hoc | AK26: =IF(AB26="","",AI26*AJ26/8) -> 0 | BW26: z
B27: =IF(AD27="","",IF(ISERROR(FIND(CHAR(10),AD27,1)),AD27,LEFT(AD27,FIND(CHAR(10),AD27,1)))) -> 03-01-22: init | C27: =IF(AD27="","",IFERROR(RIGHT(AD27,LEN(AD27)-FIND("@@@",SUBSTITUTE(AD27,CHAR(10),"@@@",LEN(AD27)-LEN(SUBSTITUTE(AD27,CHAR(10),""))),1)),AD27)) -> 03-01-22: init | D27: =IFERROR(DATE(("20"&MID(B27,7,2))*1,MID(B27,4,2)*1,MID(B27,1,2)*1),"") -> 44564 | E27: =IFERROR(DATE(("20"&MID(C27,7,2))*1,MID(C27,4,2)*1,MID(C27,1,2)*1),"") -> 44564 | F27: =MAX(D27,IF(E27="none",D27,E27)) -> 44564 | G27: =IFERROR(DAYS360(D27,F27),0) -> 0 | H27: =((LEN($AE27)-LEN(SUBSTITUTE($AE27,CHAR(10)&". ","")))/3)+IF(LEFT(TRIM($AE27),2)=". ",1,0) -> 0 | I27: =((LEN($AE27)-LEN(SUBSTITUTE($AE27,CHAR(10)&"/ ","")))/3)+IF(LEFT(TRIM($AE27),2)="/ ",1,0) -> 0 | J27: =((LEN($AE27)-LEN(SUBSTITUTE($AE27,CHAR(10)&"~ ","")))/3)+IF(LEFT(TRIM($AE27),2)="~ ",1,0) -> 0 | K27: =((LEN($AE27)-LEN(SUBSTITUTE($AE27,CHAR(10)&"! ","")))/3)+IF(LEFT(TRIM($AE27),2)="! ",1,0) -> 0 | L27: =((LEN($AE27)-LEN(SUBSTITUTE($AE27,CHAR(10)&"x ","")))/3)+IF(LEFT(TRIM($AE27),2)="x ",1,0) -> 0 | M27: =SUM(H27:L27) -> 0 | N27: =IF(F27>(($A$21-WEEKDAY($A$21,2))-7*$F$22),"Y","N") -> N | O27: =IF(AB27=""," - ZZZ"," - "&X27&Y27&AB27) -> - 02.organisingGeneral Management00.Maintain Organising | P27: =IF(AB27="","",(IF(OR(Q27="Y",Q27="N"),Q27,IF(N27="Y","Y","N")))) -> N | Q27: N | S27: VNT | T27: _all | U27: n/a | V27: Sander | W27: mgt | X27: 02.organising | Y27: General Management | Z27: Routine | AA27: Started | AB27: 00.Maintain Organising | AC27: Details: # INTRODUCTION Details of this management item are in the Management Framework. | AD27: 03-01-22: init | AE27: ## Generic Routines & 01.Maintain Activities [## Activities] & 02.Maintain Groups [## Groups] & 03.Maintain Delegating [## Delegating] & 04.Maintain R&R [## R&R] & 05.Maintain Casting [## Casting] & 06.Maintain Funding [## Funding] ________________________________________ ## Activities ________________________________________ ## Groups ________________________________________ ## R&R ________________________________________ ## Casting ________________________________________ ## Funding ## _END | AF27: =IF(AB27="","",SUM(H27:K27)) -> 0 | AG27: =IF(AB27="","",IF(M27<>0,(I27*0.5+L27)/M27,1)) -> 1 | AH27: Ad-hoc | AK27: =IF(AB27="","",AI27*AJ27/8) -> 0 | BW27: z
B28: =IF(AD28="","",IF(ISERROR(FIND(CHAR(10),AD28,1)),AD28,LEFT(AD28,FIND(CHAR(10),AD28,1)))) -> 03-01-22: init | C28: =IF(AD28="","",IFERROR(RIGHT(AD28,LEN(AD28)-FIND("@@@",SUBSTITUTE(AD28,CHAR(10),"@@@",LEN(AD28)-LEN(SUBSTITUTE(AD28,CHAR(10),""))),1)),AD28)) -> 03-01-22: init | D28: =IFERROR(DATE(("20"&MID(B28,7,2))*1,MID(B28,4,2)*1,MID(B28,1,2)*1),"") -> 44564 | E28: =IFERROR(DATE(("20"&MID(C28,7,2))*1,MID(C28,4,2)*1,MID(C28,1,2)*1),"") -> 44564 | F28: =MAX(D28,IF(E28="none",D28,E28)) -> 44564 | G28: =IFERROR(DAYS360(D28,F28),0) -> 0 | H28: =((LEN($AE28)-LEN(SUBSTITUTE($AE28,CHAR(10)&". ","")))/3)+IF(LEFT(TRIM($AE28),2)=". ",1,0) -> 0 | I28: =((LEN($AE28)-LEN(SUBSTITUTE($AE28,CHAR(10)&"/ ","")))/3)+IF(LEFT(TRIM($AE28),2)="/ ",1,0) -> 0 | J28: =((LEN($AE28)-LEN(SUBSTITUTE($AE28,CHAR(10)&"~ ","")))/3)+IF(LEFT(TRIM($AE28),2)="~ ",1,0) -> 0 | K28: =((LEN($AE28)-LEN(SUBSTITUTE($AE28,CHAR(10)&"! ","")))/3)+IF(LEFT(TRIM($AE28),2)="! ",1,0) -> 0 | L28: =((LEN($AE28)-LEN(SUBSTITUTE($AE28,CHAR(10)&"x ","")))/3)+IF(LEFT(TRIM($AE28),2)="x ",1,0) -> 0 | M28: =SUM(H28:L28) -> 0 | N28: =IF(F28>(($A$21-WEEKDAY($A$21,2))-7*$F$22),"Y","N") -> N | O28: =IF(AB28=""," - ZZZ"," - "&X28&Y28&AB28) -> - 03.leadingGeneral Management00.Maintain Leading | P28: =IF(AB28="","",(IF(OR(Q28="Y",Q28="N"),Q28,IF(N28="Y","Y","N")))) -> N | Q28: N | S28: VNT | T28: _all | U28: n/a | V28: Sander | W28: mgt | X28: 03.leading | Y28: General Management | Z28: Routine | AA28: Started | AB28: 00.Maintain Leading | AC28: Details: # INTRODUCTION Details of this management item are in the Management Framework. | AD28: 03-01-22: init | AE28: ## Generic Routines & 01.Maintain Safe Space [## Safe Space] & 02.Maintain Direction [## Direction] & 03.Maintain Collaboration [## Collaboration] & 04.Maintain Motivation [## Motivation] & 05.Maintain Inspiration [## Inspiration] & 06.Maintain Learning [## Learning] & 07.Maintain Networking [## Networking] & 08.Maintain Leaders [## Leaders] & 09.Maintain Management Improvement [## Management Improvement] & 10.Maintain Culture [## Culture] ________________________________________ ## Safe Space ________________________________________ ## Direction ________________________________________ ## Collaboration ________________________________________ ## Motivation ________________________________________ ## Inspiration ________________________________________ ## Learning ________________________________________ ## Networking ________________________________________ ## Leaders ________________________________________ ## Management Improvement ________________________________________ ## Culture ## _END | AF28: =IF(AB28="","",SUM(H28:K28)) -> 0 | AG28: =IF(AB28="","",IF(M28<>0,(I28*0.5+L28)/M28,1)) -> 1 | AH28: Ad-hoc | AK28: =IF(AB28="","",AI28*AJ28/8) -> 0 | BW28: z
B29: =IF(AD29="","",IF(ISERROR(FIND(CHAR(10),AD29,1)),AD29,LEFT(AD29,FIND(CHAR(10),AD29,1)))) -> 03-01-22: init | C29: =IF(AD29="","",IFERROR(RIGHT(AD29,LEN(AD29)-FIND("@@@",SUBSTITUTE(AD29,CHAR(10),"@@@",LEN(AD29)-LEN(SUBSTITUTE(AD29,CHAR(10),""))),1)),AD29)) -> 03-01-22: init | D29: =IFERROR(DATE(("20"&MID(B29,7,2))*1,MID(B29,4,2)*1,MID(B29,1,2)*1),"") -> 44564 | E29: =IFERROR(DATE(("20"&MID(C29,7,2))*1,MID(C29,4,2)*1,MID(C29,1,2)*1),"") -> 44564 | F29: =MAX(D29,IF(E29="none",D29,E29)) -> 44564 | G29: =IFERROR(DAYS360(D29,F29),0) -> 0 | H29: =((LEN($AE29)-LEN(SUBSTITUTE($AE29,CHAR(10)&". ","")))/3)+IF(LEFT(TRIM($AE29),2)=". ",1,0) -> 0 | I29: =((LEN($AE29)-LEN(SUBSTITUTE($AE29,CHAR(10)&"/ ","")))/3)+IF(LEFT(TRIM($AE29),2)="/ ",1,0) -> 0 | J29: =((LEN($AE29)-LEN(SUBSTITUTE($AE29,CHAR(10)&"~ ","")))/3)+IF(LEFT(TRIM($AE29),2)="~ ",1,0) -> 0 | K29: =((LEN($AE29)-LEN(SUBSTITUTE($AE29,CHAR(10)&"! ","")))/3)+IF(LEFT(TRIM($AE29),2)="! ",1,0) -> 0 | L29: =((LEN($AE29)-LEN(SUBSTITUTE($AE29,CHAR(10)&"x ","")))/3)+IF(LEFT(TRIM($AE29),2)="x ",1,0) -> 0 | M29: =SUM(H29:L29) -> 0 | N29: =IF(F29>(($A$21-WEEKDAY($A$21,2))-7*$F$22),"Y","N") -> N | O29: =IF(AB29=""," - ZZZ"," - "&X29&Y29&AB29) -> - 04.controllingGeneral Management00.Maintain Controlling | P29: =IF(AB29="","",(IF(OR(Q29="Y",Q29="N"),Q29,IF(N29="Y","Y","N")))) -> N | Q29: N | S29: VNT | T29: _all | U29: n/a | V29: Sander | W29: mgt | X29: 04.controlling | Y29: General Management | Z29: Routine | AA29: Started | AB29: 00.Maintain Controlling | AC29: Details: # INTRODUCTION Details of this management item are in the Management Framework. | AD29: 03-01-22: init | AE29: ## Generic Routines & 01.Maintain Jounal [## Jounal] & 02.Maintain Supervision [## Supervision] & 03.Maintain Reports [## Reports] & 04.Maintain Monitoring [## Monitoring] ________________________________________ ## Jounal ________________________________________ ## Supervision ________________________________________ ## Reports ________________________________________ ## Monitoring ## _END | AF29: =IF(AB29="","",SUM(H29:K29)) -> 0 | AG29: =IF(AB29="","",IF(M29<>0,(I29*0.5+L29)/M29,1)) -> 1 | AH29: Ad-hoc | AK29: =IF(AB29="","",AI29*AJ29/8) -> 0 | BW29: z
B30: =IF(AD30="","",IF(ISERROR(FIND(CHAR(10),AD30,1)),AD30,LEFT(AD30,FIND(CHAR(10),AD30,1)))) -> 03-01-22: init | C30: =IF(AD30="","",IFERROR(RIGHT(AD30,LEN(AD30)-FIND("@@@",SUBSTITUTE(AD30,CHAR(10),"@@@",LEN(AD30)-LEN(SUBSTITUTE(AD30,CHAR(10),""))),1)),AD30)) -> 03-01-22: init | D30: =IFERROR(DATE(("20"&MID(B30,7,2))*1,MID(B30,4,2)*1,MID(B30,1,2)*1),"") -> 44564 | E30: =IFERROR(DATE(("20"&MID(C30,7,2))*1,MID(C30,4,2)*1,MID(C30,1,2)*1),"") -> 44564 | F30: =MAX(D30,IF(E30="none",D30,E30)) -> 44564 | G30: =IFERROR(DAYS360(D30,F30),0) -> 0 | H30: =((LEN($AE30)-LEN(SUBSTITUTE($AE30,CHAR(10)&". ","")))/3)+IF(LEFT(TRIM($AE30),2)=". ",1,0) -> 0 | I30: =((LEN($AE30)-LEN(SUBSTITUTE($AE30,CHAR(10)&"/ ","")))/3)+IF(LEFT(TRIM($AE30),2)="/ ",1,0) -> 0 | J30: =((LEN($AE30)-LEN(SUBSTITUTE($AE30,CHAR(10)&"~ ","")))/3)+IF(LEFT(TRIM($AE30),2)="~ ",1,0) -> 0 | K30: =((LEN($AE30)-LEN(SUBSTITUTE($AE30,CHAR(10)&"! ","")))/3)+IF(LEFT(TRIM($AE30),2)="! ",1,0) -> 0 | L30: =((LEN($AE30)-LEN(SUBSTITUTE($AE30,CHAR(10)&"x ","")))/3)+IF(LEFT(TRIM($AE30),2)="x ",1,0) -> 0 | M30: =SUM(H30:L30) -> 0 | N30: =IF(F30>(($A$21-WEEKDAY($A$21,2))-7*$F$22),"Y","N") -> N | O30: =IF(AB30=""," - ZZZ"," - "&X30&Y30&AB30) -> - 05.00.business functionsGeneral Management00.Maintain Business Functions | P30: =IF(AB30="","",(IF(OR(Q30="Y",Q30="N"),Q30,IF(N30="Y","Y","N")))) -> N | Q30: N | S30: VNT | T30: _all | U30: n/a | V30: Sander | W30: mgt | X30: 05.00.business functions | Y30: General Management | Z30: Routine | AA30: Started | AB30: 00.Maintain Business Functions | AC30: Details: # INTRODUCTION Details of this management item are in the Management Framework. | AD30: 03-01-22: init | AE30: ## Generic Routines ## _END | AF30: =IF(AB30="","",SUM(H30:K30)) -> 0 | AG30: =IF(AB30="","",IF(M30<>0,(I30*0.5+L30)/M30,1)) -> 1 | AH30: Ad-hoc | AK30: =IF(AB30="","",AI30*AJ30/8) -> 0 | BW30: z
B31: =IF(AD31="","",IF(ISERROR(FIND(CHAR(10),AD31,1)),AD31,LEFT(AD31,FIND(CHAR(10),AD31,1)))) -> 03-01-22: init | C31: =IF(AD31="","",IFERROR(RIGHT(AD31,LEN(AD31)-FIND("@@@",SUBSTITUTE(AD31,CHAR(10),"@@@",LEN(AD31)-LEN(SUBSTITUTE(AD31,CHAR(10),""))),1)),AD31)) -> 03-01-22: init | D31: =IFERROR(DATE(("20"&MID(B31,7,2))*1,MID(B31,4,2)*1,MID(B31,1,2)*1),"") -> 44564 | E31: =IFERROR(DATE(("20"&MID(C31,7,2))*1,MID(C31,4,2)*1,MID(C31,1,2)*1),"") -> 44564 | F31: =MAX(D31,IF(E31="none",D31,E31)) -> 44564 | G31: =IFERROR(DAYS360(D31,F31),0) -> 0 | H31: =((LEN($AE31)-LEN(SUBSTITUTE($AE31,CHAR(10)&". ","")))/3)+IF(LEFT(TRIM($AE31),2)=". ",1,0) -> 0 | I31: =((LEN($AE31)-LEN(SUBSTITUTE($AE31,CHAR(10)&"/ ","")))/3)+IF(LEFT(TRIM($AE31),2)="/ ",1,0) -> 0 | J31: =((LEN($AE31)-LEN(SUBSTITUTE($AE31,CHAR(10)&"~ ","")))/3)+IF(LEFT(TRIM($AE31),2)="~ ",1,0) -> 0 | K31: =((LEN($AE31)-LEN(SUBSTITUTE($AE31,CHAR(10)&"! ","")))/3)+IF(LEFT(TRIM($AE31),2)="! ",1,0) -> 0 | L31: =((LEN($AE31)-LEN(SUBSTITUTE($AE31,CHAR(10)&"x ","")))/3)+IF(LEFT(TRIM($AE31),2)="x ",1,0) -> 0 | M31: =SUM(H31:L31) -> 0 | N31: =IF(F31>(($A$21-WEEKDAY($A$21,2))-7*$F$22),"Y","N") -> N | O31: =IF(AB31=""," - ZZZ"," - "&X31&Y31&AB31) -> - 05.01.financeGeneral Management00.Maintain Finance | P31: =IF(AB31="","",(IF(OR(Q31="Y",Q31="N"),Q31,IF(N31="Y","Y","N")))) -> N | Q31: N | S31: VNT | T31: _all | U31: n/a | V31: Sander | W31: mgt | X31: 05.01.finance | Y31: General Management | Z31: Routine | AA31: Started | AB31: 00.Maintain Finance | AC31: Details: # INTRODUCTION Details of this management item are in the Management Framework. | AD31: 03-01-22: init | AE31: ## Generic Routines & 01.Maintain Accounting [## Accounting] & 02.Maintain Financing [## Financing] ________________________________________ ## Accounting ________________________________________ ## Financing ## _END | AF31: =IF(AB31="","",SUM(H31:K31)) -> 0 | AG31: =IF(AB31="","",IF(M31<>0,(I31*0.5+L31)/M31,1)) -> 1 | AH31: Ad-hoc | AK31: =IF(AB31="","",AI31*AJ31/8) -> 0 | BW31: z
B32: =IF(AD32="","",IF(ISERROR(FIND(CHAR(10),AD32,1)),AD32,LEFT(AD32,FIND(CHAR(10),AD32,1)))) -> 03-01-22: init | C32: =IF(AD32="","",IFERROR(RIGHT(AD32,LEN(AD32)-FIND("@@@",SUBSTITUTE(AD32,CHAR(10),"@@@",LEN(AD32)-LEN(SUBSTITUTE(AD32,CHAR(10),""))),1)),AD32)) -> 03-01-22: init | D32: =IFERROR(DATE(("20"&MID(B32,7,2))*1,MID(B32,4,2)*1,MID(B32,1,2)*1),"") -> 44564 | E32: =IFERROR(DATE(("20"&MID(C32,7,2))*1,MID(C32,4,2)*1,MID(C32,1,2)*1),"") -> 44564 | F32: =MAX(D32,IF(E32="none",D32,E32)) -> 44564 | G32: =IFERROR(DAYS360(D32,F32),0) -> 0 | H32: =((LEN($AE32)-LEN(SUBSTITUTE($AE32,CHAR(10)&". ","")))/3)+IF(LEFT(TRIM($AE32),2)=". ",1,0) -> 0 | I32: =((LEN($AE32)-LEN(SUBSTITUTE($AE32,CHAR(10)&"/ ","")))/3)+IF(LEFT(TRIM($AE32),2)="/ ",1,0) -> 0 | J32: =((LEN($AE32)-LEN(SUBSTITUTE($AE32,CHAR(10)&"~ ","")))/3)+IF(LEFT(TRIM($AE32),2)="~ ",1,0) -> 0 | K32: =((LEN($AE32)-LEN(SUBSTITUTE($AE32,CHAR(10)&"! ","")))/3)+IF(LEFT(TRIM($AE32),2)="! ",1,0) -> 0 | L32: =((LEN($AE32)-LEN(SUBSTITUTE($AE32,CHAR(10)&"x ","")))/3)+IF(LEFT(TRIM($AE32),2)="x ",1,0) -> 0 | M32: =SUM(H32:L32) -> 0 | N32: =IF(F32>(($A$21-WEEKDAY($A$21,2))-7*$F$22),"Y","N") -> N | O32: =IF(AB32=""," - ZZZ"," - "&X32&Y32&AB32) -> - 05.02.HRGeneral Management00.Maintain HR | P32: =IF(AB32="","",(IF(OR(Q32="Y",Q32="N"),Q32,IF(N32="Y","Y","N")))) -> N | Q32: N | S32: VNT | T32: _all | U32: n/a | V32: Sander | W32: mgt | X32: 05.02.HR | Y32: General Management | Z32: Routine | AA32: Started | AB32: 00.Maintain HR | AC32: Details: # INTRODUCTION Details of this management item are in the Management Framework. | AD32: 03-01-22: init | AE32: ## Generic Routines & 01.Maintain Recruitment [## Recruitment] & 02.Maintain Skills & Knowledge [## Skills & Knowledge] & 03.Maintain Training [## Training] & 04.Maintain Performance [## Performance] & 05.Maintain Remuneration [## Remuneration] & 06.Maintain Job Satifactions [## Learning] & 07.Maintain Employee Relations [## Employee Relations] & 08.Maintain Employment Law [## Employment Law] ________________________________________ ## Recruitment ________________________________________ ## Skills & Knowledge ________________________________________ ## Training ________________________________________ ## Performance ________________________________________ ## Remuneration ________________________________________ ## Job Satisfacton ________________________________________ ## Employee Relations ________________________________________ ## Employment Law ## _END | AF32: =IF(AB32="","",SUM(H32:K32)) -> 0 | AG32: =IF(AB32="","",IF(M32<>0,(I32*0.5+L32)/M32,1)) -> 1 | AH32: Ad-hoc | AK32: =IF(AB32="","",AI32*AJ32/8) -> 0 | BW32: z
B33: =IF(AD33="","",IF(ISERROR(FIND(CHAR(10),AD33,1)),AD33,LEFT(AD33,FIND(CHAR(10),AD33,1)))) -> 03-01-22: init | C33: =IF(AD33="","",IFERROR(RIGHT(AD33,LEN(AD33)-FIND("@@@",SUBSTITUTE(AD33,CHAR(10),"@@@",LEN(AD33)-LEN(SUBSTITUTE(AD33,CHAR(10),""))),1)),AD33)) -> 03-01-22: init | D33: =IFERROR(DATE(("20"&MID(B33,7,2))*1,MID(B33,4,2)*1,MID(B33,1,2)*1),"") -> 44564 | E33: =IFERROR(DATE(("20"&MID(C33,7,2))*1,MID(C33,4,2)*1,MID(C33,1,2)*1),"") -> 44564 | F33: =MAX(D33,IF(E33="none",D33,E33)) -> 44564 | G33: =IFERROR(DAYS360(D33,F33),0) -> 0 | H33: =((LEN($AE33)-LEN(SUBSTITUTE($AE33,CHAR(10)&". ","")))/3)+IF(LEFT(TRIM($AE33),2)=". ",1,0) -> 0 | I33: =((LEN($AE33)-LEN(SUBSTITUTE($AE33,CHAR(10)&"/ ","")))/3)+IF(LEFT(TRIM($AE33),2)="/ ",1,0) -> 0 | J33: =((LEN($AE33)-LEN(SUBSTITUTE($AE33,CHAR(10)&"~ ","")))/3)+IF(LEFT(TRIM($AE33),2)="~ ",1,0) -> 0 | K33: =((LEN($AE33)-LEN(SUBSTITUTE($AE33,CHAR(10)&"! ","")))/3)+IF(LEFT(TRIM($AE33),2)="! ",1,0) -> 0 | L33: =((LEN($AE33)-LEN(SUBSTITUTE($AE33,CHAR(10)&"x ","")))/3)+IF(LEFT(TRIM($AE33),2)="x ",1,0) -> 0 | M33: =SUM(H33:L33) -> 0 | N33: =IF(F33>(($A$21-WEEKDAY($A$21,2))-7*$F$22),"Y","N") -> N | O33: =IF(AB33=""," - ZZZ"," - "&X33&Y33&AB33) -> - 05.03.ITGeneral Management00.Maintain IT | P33: =IF(AB33="","",(IF(OR(Q33="Y",Q33="N"),Q33,IF(N33="Y","Y","N")))) -> N | Q33: N | S33: VNT | T33: _all | U33: n/a | V33: Sander | W33: mgt | X33: 05.03.IT | Y33: General Management | Z33: Routine | AA33: Started | AB33: 00.Maintain IT | AC33: Details: # INTRODUCTION Details of this management item are in the Management Framework. | AD33: 03-01-22: init | AE33: ## Generic Routines & 01.Maintain Infra [## Infra] & 02.Maintain Applications [## Applications] ________________________________________ ## Infra ________________________________________ ## Applications ## _END | AF33: =IF(AB33="","",SUM(H33:K33)) -> 0 | AG33: =IF(AB33="","",IF(M33<>0,(I33*0.5+L33)/M33,1)) -> 1 | AH33: Ad-hoc | AK33: =IF(AB33="","",AI33*AJ33/8) -> 0 | BW33: z
B34: =IF(AD34="","",IF(ISERROR(FIND(CHAR(10),AD34,1)),AD34,LEFT(AD34,FIND(CHAR(10),AD34,1)))) -> 03-01-22: init | C34: =IF(AD34="","",IFERROR(RIGHT(AD34,LEN(AD34)-FIND("@@@",SUBSTITUTE(AD34,CHAR(10),"@@@",LEN(AD34)-LEN(SUBSTITUTE(AD34,CHAR(10),""))),1)),AD34)) -> 03-01-22: init | D34: =IFERROR(DATE(("20"&MID(B34,7,2))*1,MID(B34,4,2)*1,MID(B34,1,2)*1),"") -> 44564 | E34: =IFERROR(DATE(("20"&MID(C34,7,2))*1,MID(C34,4,2)*1,MID(C34,1,2)*1),"") -> 44564 | F34: =MAX(D34,IF(E34="none",D34,E34)) -> 44564 | G34: =IFERROR(DAYS360(D34,F34),0) -> 0 | H34: =((LEN($AE34)-LEN(SUBSTITUTE($AE34,CHAR(10)&". ","")))/3)+IF(LEFT(TRIM($AE34),2)=". ",1,0) -> 0 | I34: =((LEN($AE34)-LEN(SUBSTITUTE($AE34,CHAR(10)&"/ ","")))/3)+IF(LEFT(TRIM($AE34),2)="/ ",1,0) -> 0 | J34: =((LEN($AE34)-LEN(SUBSTITUTE($AE34,CHAR(10)&"~ ","")))/3)+IF(LEFT(TRIM($AE34),2)="~ ",1,0) -> 0 | K34: =((LEN($AE34)-LEN(SUBSTITUTE($AE34,CHAR(10)&"! ","")))/3)+IF(LEFT(TRIM($AE34),2)="! ",1,0) -> 0 | L34: =((LEN($AE34)-LEN(SUBSTITUTE($AE34,CHAR(10)&"x ","")))/3)+IF(LEFT(TRIM($AE34),2)="x ",1,0) -> 0 | M34: =SUM(H34:L34) -> 0 | N34: =IF(F34>(($A$21-WEEKDAY($A$21,2))-7*$F$22),"Y","N") -> N | O34: =IF(AB34=""," - ZZZ"," - "&X34&Y34&AB34) -> - 05.04.riskGeneral Management00.Maintain Risk | P34: =IF(AB34="","",(IF(OR(Q34="Y",Q34="N"),Q34,IF(N34="Y","Y","N")))) -> N | Q34: N | S34: VNT | T34: _all | U34: n/a | V34: Sander | W34: mgt | X34: 05.04.risk | Y34: General Management | Z34: Routine | AA34: Started | AB34: 00.Maintain Risk | AC34: Details: # INTRODUCTION Details of this management item are in the Management Framework. | AD34: 03-01-22: init | AE34: ## Generic Routines ________________________________________ ## _END | AF34: =IF(AB34="","",SUM(H34:K34)) -> 0 | AG34: =IF(AB34="","",IF(M34<>0,(I34*0.5+L34)/M34,1)) -> 1 | AH34: Ad-hoc | AK34: =IF(AB34="","",AI34*AJ34/8) -> 0 | BW34: z
B35: =IF(AD35="","",IF(ISERROR(FIND(CHAR(10),AD35,1)),AD35,LEFT(AD35,FIND(CHAR(10),AD35,1)))) -> 03-01-22: init | C35: =IF(AD35="","",IFERROR(RIGHT(AD35,LEN(AD35)-FIND("@@@",SUBSTITUTE(AD35,CHAR(10),"@@@",LEN(AD35)-LEN(SUBSTITUTE(AD35,CHAR(10),""))),1)),AD35)) -> 03-01-22: init | D35: =IFERROR(DATE(("20"&MID(B35,7,2))*1,MID(B35,4,2)*1,MID(B35,1,2)*1),"") -> 44564 | E35: =IFERROR(DATE(("20"&MID(C35,7,2))*1,MID(C35,4,2)*1,MID(C35,1,2)*1),"") -> 44564 | F35: =MAX(D35,IF(E35="none",D35,E35)) -> 44564 | G35: =IFERROR(DAYS360(D35,F35),0) -> 0 | H35: =((LEN($AE35)-LEN(SUBSTITUTE($AE35,CHAR(10)&". ","")))/3)+IF(LEFT(TRIM($AE35),2)=". ",1,0) -> 0 | I35: =((LEN($AE35)-LEN(SUBSTITUTE($AE35,CHAR(10)&"/ ","")))/3)+IF(LEFT(TRIM($AE35),2)="/ ",1,0) -> 0 | J35: =((LEN($AE35)-LEN(SUBSTITUTE($AE35,CHAR(10)&"~ ","")))/3)+IF(LEFT(TRIM($AE35),2)="~ ",1,0) -> 0 | K35: =((LEN($AE35)-LEN(SUBSTITUTE($AE35,CHAR(10)&"! ","")))/3)+IF(LEFT(TRIM($AE35),2)="! ",1,0) -> 0 | L35: =((LEN($AE35)-LEN(SUBSTITUTE($AE35,CHAR(10)&"x ","")))/3)+IF(LEFT(TRIM($AE35),2)="x ",1,0) -> 0 | M35: =SUM(H35:L35) -> 0 | N35: =IF(F35>(($A$21-WEEKDAY($A$21,2))-7*$F$22),"Y","N") -> N | O35: =IF(AB35=""," - ZZZ"," - "&X35&Y35&AB35) -> - 05.05.complianceGeneral Management00.Maintain Compliance | P35: =IF(AB35="","",(IF(OR(Q35="Y",Q35="N"),Q35,IF(N35="Y","Y","N")))) -> N | Q35: N | S35: VNT | T35: _all | U35: n/a | V35: Sander | W35: mgt | X35: 05.05.compliance | Y35: General Management | Z35: Routine | AA35: Started | AB35: 00.Maintain Compliance | AC35: Details: # INTRODUCTION Details of this management item are in the Management Framework. | AD35: 03-01-22: init | AE35: ## Generic Routines ________________________________________ ## _END | AF35: =IF(AB35="","",SUM(H35:K35)) -> 0 | AG35: =IF(AB35="","",IF(M35<>0,(I35*0.5+L35)/M35,1)) -> 1 | AH35: Ad-hoc | AK35: =IF(AB35="","",AI35*AJ35/8) -> 0 | BW35: z
B36: =IF(AD36="","",IF(ISERROR(FIND(CHAR(10),AD36,1)),AD36,LEFT(AD36,FIND(CHAR(10),AD36,1)))) -> 03-01-22: init | C36: =IF(AD36="","",IFERROR(RIGHT(AD36,LEN(AD36)-FIND("@@@",SUBSTITUTE(AD36,CHAR(10),"@@@",LEN(AD36)-LEN(SUBSTITUTE(AD36,CHAR(10),""))),1)),AD36)) -> 03-01-22: init | D36: =IFERROR(DATE(("20"&MID(B36,7,2))*1,MID(B36,4,2)*1,MID(B36,1,2)*1),"") -> 44564 | E36: =IFERROR(DATE(("20"&MID(C36,7,2))*1,MID(C36,4,2)*1,MID(C36,1,2)*1),"") -> 44564 | F36: =MAX(D36,IF(E36="none",D36,E36)) -> 44564 | G36: =IFERROR(DAYS360(D36,F36),0) -> 0 | H36: =((LEN($AE36)-LEN(SUBSTITUTE($AE36,CHAR(10)&". ","")))/3)+IF(LEFT(TRIM($AE36),2)=". ",1,0) -> 0 | I36: =((LEN($AE36)-LEN(SUBSTITUTE($AE36,CHAR(10)&"/ ","")))/3)+IF(LEFT(TRIM($AE36),2)="/ ",1,0) -> 0 | J36: =((LEN($AE36)-LEN(SUBSTITUTE($AE36,CHAR(10)&"~ ","")))/3)+IF(LEFT(TRIM($AE36),2)="~ ",1,0) -> 0 | K36: =((LEN($AE36)-LEN(SUBSTITUTE($AE36,CHAR(10)&"! ","")))/3)+IF(LEFT(TRIM($AE36),2)="! ",1,0) -> 0 | L36: =((LEN($AE36)-LEN(SUBSTITUTE($AE36,CHAR(10)&"x ","")))/3)+IF(LEFT(TRIM($AE36),2)="x ",1,0) -> 0 | M36: =SUM(H36:L36) -> 0 | N36: =IF(F36>(($A$21-WEEKDAY($A$21,2))-7*$F$22),"Y","N") -> N | O36: =IF(AB36=""," - ZZZ"," - "&X36&Y36&AB36) -> - 05.06.legalGeneral Management00.Maintain Legal | P36: =IF(AB36="","",(IF(OR(Q36="Y",Q36="N"),Q36,IF(N36="Y","Y","N")))) -> N | Q36: N | S36: VNT | T36: _all | U36: n/a | V36: Sander | W36: mgt | X36: 05.06.legal | Y36: General Management | Z36: Routine | AA36: Started | AB36: 00.Maintain Legal | AC36: Details: # INTRODUCTION Details of this management item are in the Management Framework. | AD36: 03-01-22: init | AE36: ## Generic Routines & 01.Maintain Legal Opinions [## Legal Opinions] & 02.Maintain Litigation [## Financing] & 03.Maintain Entty Structure [## Entity Structure] ________________________________________ ## Legal Opinions ________________________________________ ## Litigation ________________________________________ ## Entity Structure ## _END | AF36: =IF(AB36="","",SUM(H36:K36)) -> 0 | AG36: =IF(AB36="","",IF(M36<>0,(I36*0.5+L36)/M36,1)) -> 1 | AH36: Ad-hoc | AK36: =IF(AB36="","",AI36*AJ36/8) -> 0 | BW36: z
... B43: =IF(AD43="","",IF(ISERROR(FIND(CHAR(10),AD43,1)),AD43,LEFT(AD43,FIND(CHAR(10),AD43,1)))) -> 03-01-22: init | C43: =IF(AD43="","",IFERROR(RIGHT(AD43,LEN(AD43)-FIND("@@@",SUBSTITUTE(AD43,CHAR(10),"@@@",LEN(AD43)-LEN(SUBSTITUTE(AD43,CHAR(10),""))),1)),AD43)) -> 03-01-22: init | D43: =IFERROR(DATE(("20"&MID(B43,7,2))*1,MID(B43,4,2)*1,MID(B43,1,2)*1),"") -> 44564 | E43: =IFERROR(DATE(("20"&MID(C43,7,2))*1,MID(C43,4,2)*1,MID(C43,1,2)*1),"") -> 44564 | F43: =MAX(D43,IF(E43="none",D43,E43)) -> 44564 | G43: =IFERROR(DAYS360(D43,F43),0) -> 0 | H43: =((LEN($AE43)-LEN(SUBSTITUTE($AE43,CHAR(10)&". ","")))/3)+IF(LEFT(TRIM($AE43),2)=". ",1,0) -> 0 | I43: =((LEN($AE43)-LEN(SUBSTITUTE($AE43,CHAR(10)&"/ ","")))/3)+IF(LEFT(TRIM($AE43),2)="/ ",1,0) -> 0 | J43: =((LEN($AE43)-LEN(SUBSTITUTE($AE43,CHAR(10)&"~ ","")))/3)+IF(LEFT(TRIM($AE43),2)="~ ",1,0) -> 0 | K43: =((LEN($AE43)-LEN(SUBSTITUTE($AE43,CHAR(10)&"! ","")))/3)+IF(LEFT(TRIM($AE43),2)="! ",1,0) -> 0 | L43: =((LEN($AE43)-LEN(SUBSTITUTE($AE43,CHAR(10)&"x ","")))/3)+IF(LEFT(TRIM($AE43),2)="x ",1,0) -> 0 | M43: =SUM(H43:L43) -> 0 | N43: =IF(F43>(($A$21-WEEKDAY($A$21,2))-7*$F$22),"Y","N") -> N | O43: =IF(AB43=""," - ZZZ"," - "&X43&Y43&AB43) -> - 06.toolsGeneral Management00.Maintain Tools | P43: =IF(AB43="","",(IF(OR(Q43="Y",Q43="N"),Q43,IF(N43="Y","Y","N")))) -> N | Q43: N | S43: VNT | T43: _all | U43: n/a | V43: Sander | W43: mgt | X43: 06.tools | Y43: General Management | Z43: Routine | AA43: Started | AB43: 00.Maintain Tools | AC43: Details: # INTRODUCTION Details of this management item are in the Management Framework. | AD43: 03-01-22: init | AE43: ## Generic Routines ________________________________________ ## _END | AF43: =IF(AB43="","",SUM(H43:K43)) -> 0 | AG43: =IF(AB43="","",IF(M43<>0,(I43*0.5+L43)/M43,1)) -> 1 | AH43: Ad-hoc | AK43: =IF(AB43="","",AI43*AJ43/8) -> 0 | BW43: z
B44: =IF(AD44="","",IF(ISERROR(FIND(CHAR(10),AD44,1)),AD44,LEFT(AD44,FIND(CHAR(10),AD44,1)))) -> 03-01-22: init | C44: =IF(AD44="","",IFERROR(RIGHT(AD44,LEN(AD44)-FIND("@@@",SUBSTITUTE(AD44,CHAR(10),"@@@",LEN(AD44)-LEN(SUBSTITUTE(AD44,CHAR(10),""))),1)),AD44)) -> 03-01-22: init | D44: =IFERROR(DATE(("20"&MID(B44,7,2))*1,MID(B44,4,2)*1,MID(B44,1,2)*1),"") -> 44564 | E44: =IFERROR(DATE(("20"&MID(C44,7,2))*1,MID(C44,4,2)*1,MID(C44,1,2)*1),"") -> 44564 | F44: =MAX(D44,IF(E44="none",D44,E44)) -> 44564 | G44: =IFERROR(DAYS360(D44,F44),0) -> 0 | H44: =((LEN($AE44)-LEN(SUBSTITUTE($AE44,CHAR(10)&". ","")))/3)+IF(LEFT(TRIM($AE44),2)=". ",1,0) -> 0 | I44: =((LEN($AE44)-LEN(SUBSTITUTE($AE44,CHAR(10)&"/ ","")))/3)+IF(LEFT(TRIM($AE44),2)="/ ",1,0) -> 0 | J44: =((LEN($AE44)-LEN(SUBSTITUTE($AE44,CHAR(10)&"~ ","")))/3)+IF(LEFT(TRIM($AE44),2)="~ ",1,0) -> 0 | K44: =((LEN($AE44)-LEN(SUBSTITUTE($AE44,CHAR(10)&"! ","")))/3)+IF(LEFT(TRIM($AE44),2)="! ",1,0) -> 0 | L44: =((LEN($AE44)-LEN(SUBSTITUTE($AE44,CHAR(10)&"x ","")))/3)+IF(LEFT(TRIM($AE44),2)="x ",1,0) -> 0 | M44: =SUM(H44:L44) -> 0 | N44: =IF(F44>(($A$21-WEEKDAY($A$21,2))-7*$F$22),"Y","N") -> N | O44: =IF(AB44=""," - ZZZ"," - "&X44&Y44&AB44) -> - 07.management cycleGeneral Management00.Maintain Management Cycle | P44: =IF(AB44="","",(IF(OR(Q44="Y",Q44="N"),Q44,IF(N44="Y","Y","N")))) -> N | Q44: N | S44: VNT | T44: _all | U44: n/a | V44: Sander | W44: mgt | X44: 07.management cycle | Y44: General Management | Z44: Routine | AA44: Started | AB44: 00.Maintain Management Cycle | AC44: Details: # INTRODUCTION Details of this management item are in the Management Framework. | AD44: 03-01-22: init | AE44: ## Generic Routines ________________________________________ ## _END | AF44: =IF(AB44="","",SUM(H44:K44)) -> 0 | AG44: =IF(AB44="","",IF(M44<>0,(I44*0.5+L44)/M44,1)) -> 1 | AK44: =IF(AB44="","",AI44*AJ44/8) -> 0 | BW44: z
B45: =IF(AD45="","",IF(ISERROR(FIND(CHAR(10),AD45,1)),AD45,LEFT(AD45,FIND(CHAR(10),AD45,1)))) | C45: =IF(AD45="","",IFERROR(RIGHT(AD45,LEN(AD45)-FIND("@@@",SUBSTITUTE(AD45,CHAR(10),"@@@",LEN(AD45)-LEN(SUBSTITUTE(AD45,CHAR(10),""))),1)),AD45)) | D45: =IFERROR(DATE(("20"&MID(B45,7,2))*1,MID(B45,4,2)*1,MID(B45,1,2)*1),"") | E45: =IFERROR(DATE(("20"&MID(C45,7,2))*1,MID(C45,4,2)*1,MID(C45,1,2)*1),"") | F45: =MAX(D45,IF(E45="none",D45,E45)) -> 0 | G45: =IFERROR(DAYS360(D45,F45),0) -> 0 | H45: =((LEN($AE45)-LEN(SUBSTITUTE($AE45,CHAR(10)&". ","")))/3)+IF(LEFT(TRIM($AE45),2)=". ",1,0) -> 0 | I45: =((LEN($AE45)-LEN(SUBSTITUTE($AE45,CHAR(10)&"/ ","")))/3)+IF(LEFT(TRIM($AE45),2)="/ ",1,0) -> 0 | J45: =((LEN($AE45)-LEN(SUBSTITUTE($AE45,CHAR(10)&"~ ","")))/3)+IF(LEFT(TRIM($AE45),2)="~ ",1,0) -> 0 | K45: =((LEN($AE45)-LEN(SUBSTITUTE($AE45,CHAR(10)&"! ","")))/3)+IF(LEFT(TRIM($AE45),2)="! ",1,0) -> 0 | L45: =((LEN($AE45)-LEN(SUBSTITUTE($AE45,CHAR(10)&"x ","")))/3)+IF(LEFT(TRIM($AE45),2)="x ",1,0) -> 0 | M45: =SUM(H45:L45) -> 0 | N45: =IF(F45>(($A$21-WEEKDAY($A$21,2))-7*$F$22),"Y","N") -> N | O45: =IF(AB45=""," - ZZZ"," - "&X45&Y45&AB45) -> - ZZZ | P45: =IF(AB45="","",(IF(OR(Q45="Y",Q45="N"),Q45,IF(N45="Y","Y","N")))) | AF45: =IF(AB45="","",SUM(H45:K45)) | AG45: =IF(AB45="","",IF(M45<>0,(I45*0.5+L45)/M45,1)) | AK45: =IF(AB45="","",AI45*AJ45/8) | BW45: z
B46: =IF(AD46="","",IF(ISERROR(FIND(CHAR(10),AD46,1)),AD46,LEFT(AD46,FIND(CHAR(10),AD46,1)))) | C46: =IF(AD46="","",IFERROR(RIGHT(AD46,LEN(AD46)-FIND("@@@",SUBSTITUTE(AD46,CHAR(10),"@@@",LEN(AD46)-LEN(SUBSTITUTE(AD46,CHAR(10),""))),1)),AD46)) | D46: =IFERROR(DATE(("20"&MID(B46,7,2))*1,MID(B46,4,2)*1,MID(B46,1,2)*1),"") | E46: =IFERROR(DATE(("20"&MID(C46,7,2))*1,MID(C46,4,2)*1,MID(C46,1,2)*1),"") | F46: =MAX(D46,IF(E46="none",D46,E46)) -> 0 | G46: =IFERROR(DAYS360(D46,F46),0) -> 0 | H46: =((LEN($AE46)-LEN(SUBSTITUTE($AE46,CHAR(10)&". ","")))/3)+IF(LEFT(TRIM($AE46),2)=". ",1,0) -> 0 | I46: =((LEN($AE46)-LEN(SUBSTITUTE($AE46,CHAR(10)&"/ ","")))/3)+IF(LEFT(TRIM($AE46),2)="/ ",1,0) -> 0 | J46: =((LEN($AE46)-LEN(SUBSTITUTE($AE46,CHAR(10)&"~ ","")))/3)+IF(LEFT(TRIM($AE46),2)="~ ",1,0) -> 0 | K46: =((LEN($AE46)-LEN(SUBSTITUTE($AE46,CHAR(10)&"! ","")))/3)+IF(LEFT(TRIM($AE46),2)="! ",1,0) -> 0 | L46: =((LEN($AE46)-LEN(SUBSTITUTE($AE46,CHAR(10)&"x ","")))/3)+IF(LEFT(TRIM($AE46),2)="x ",1,0) -> 0 | M46: =SUM(H46:L46) -> 0 | N46: =IF(F46>(($A$21-WEEKDAY($A$21,2))-7*$F$22),"Y","N") -> N | O46: =IF(AB46=""," - ZZZ"," - "&X46&Y46&AB46) -> - ZZZ | P46: =IF(AB46="","",(IF(OR(Q46="Y",Q46="N"),Q46,IF(N46="Y","Y","N")))) | AF46: =IF(AB46="","",SUM(H46:K46)) | AG46: =IF(AB46="","",IF(M46<>0,(I46*0.5+L46)/M46,1)) | AK46: =IF(AB46="","",AI46*AJ46/8) | BW46: z
B47: =IF(AD47="","",IF(ISERROR(FIND(CHAR(10),AD47,1)),AD47,LEFT(AD47,FIND(CHAR(10),AD47,1)))) | C47: =IF(AD47="","",IFERROR(RIGHT(AD47,LEN(AD47)-FIND("@@@",SUBSTITUTE(AD47,CHAR(10),"@@@",LEN(AD47)-LEN(SUBSTITUTE(AD47,CHAR(10),""))),1)),AD47)) | D47: =IFERROR(DATE(("20"&MID(B47,7,2))*1,MID(B47,4,2)*1,MID(B47,1,2)*1),"") | E47: =IFERROR(DATE(("20"&MID(C47,7,2))*1,MID(C47,4,2)*1,MID(C47,1,2)*1),"") | F47: =MAX(D47,IF(E47="none",D47,E47)) -> 0 | G47: =IFERROR(DAYS360(D47,F47),0) -> 0 | H47: =((LEN($AE47)-LEN(SUBSTITUTE($AE47,CHAR(10)&". ","")))/3)+IF(LEFT(TRIM($AE47),2)=". ",1,0) -> 0 | I47: =((LEN($AE47)-LEN(SUBSTITUTE($AE47,CHAR(10)&"/ ","")))/3)+IF(LEFT(TRIM($AE47),2)="/ ",1,0) -> 0 | J47: =((LEN($AE47)-LEN(SUBSTITUTE($AE47,CHAR(10)&"~ ","")))/3)+IF(LEFT(TRIM($AE47),2)="~ ",1,0) -> 0 | K47: =((LEN($AE47)-LEN(SUBSTITUTE($AE47,CHAR(10)&"! ","")))/3)+IF(LEFT(TRIM($AE47),2)="! ",1,0) -> 0 | L47: =((LEN($AE47)-LEN(SUBSTITUTE($AE47,CHAR(10)&"x ","")))/3)+IF(LEFT(TRIM($AE47),2)="x ",1,0) -> 0 | M47: =SUM(H47:L47) -> 0 | N47: =IF(F47>(($A$21-WEEKDAY($A$21,2))-7*$F$22),"Y","N") -> N | O47: =IF(AB47=""," - ZZZ"," - "&X47&Y47&AB47) -> - ZZZ | P47: =IF(AB47="","",(IF(OR(Q47="Y",Q47="N"),Q47,IF(N47="Y","Y","N")))) | AF47: =IF(AB47="","",SUM(H47:K47)) | AG47: =IF(AB47="","",IF(M47<>0,(I47*0.5+L47)/M47,1)) | AK47: =IF(AB47="","",AI47*AJ47/8) | BW47: z
B48: =IF(AD48="","",IF(ISERROR(FIND(CHAR(10),AD48,1)),AD48,LEFT(AD48,FIND(CHAR(10),AD48,1)))) | C48: =IF(AD48="","",IFERROR(RIGHT(AD48,LEN(AD48)-FIND("@@@",SUBSTITUTE(AD48,CHAR(10),"@@@",LEN(AD48)-LEN(SUBSTITUTE(AD48,CHAR(10),""))),1)),AD48)) | D48: =IFERROR(DATE(("20"&MID(B48,7,2))*1,MID(B48,4,2)*1,MID(B48,1,2)*1),"") | E48: =IFERROR(DATE(("20"&MID(C48,7,2))*1,MID(C48,4,2)*1,MID(C48,1,2)*1),"") | F48: =MAX(D48,IF(E48="none",D48,E48)) -> 0 | G48: =IFERROR(DAYS360(D48,F48),0) -> 0 | H48: =((LEN($AE48)-LEN(SUBSTITUTE($AE48,CHAR(10)&". ","")))/3)+IF(LEFT(TRIM($AE48),2)=". ",1,0) -> 0 | I48: =((LEN($AE48)-LEN(SUBSTITUTE($AE48,CHAR(10)&"/ ","")))/3)+IF(LEFT(TRIM($AE48),2)="/ ",1,0) -> 0 | J48: =((LEN($AE48)-LEN(SUBSTITUTE($AE48,CHAR(10)&"~ ","")))/3)+IF(LEFT(TRIM($AE48),2)="~ ",1,0) -> 0 | K48: =((LEN($AE48)-LEN(SUBSTITUTE($AE48,CHAR(10)&"! ","")))/3)+IF(LEFT(TRIM($AE48),2)="! ",1,0) -> 0 | L48: =((LEN($AE48)-LEN(SUBSTITUTE($AE48,CHAR(10)&"x ","")))/3)+IF(LEFT(TRIM($AE48),2)="x ",1,0) -> 0 | M48: =SUM(H48:L48) -> 0 | N48: =IF(F48>(($A$21-WEEKDAY($A$21,2))-7*$F$22),"Y","N") -> N | O48: =IF(AB48=""," - ZZZ"," - "&X48&Y48&AB48) -> - ZZZ | P48: =IF(AB48="","",(IF(OR(Q48="Y",Q48="N"),Q48,IF(N48="Y","Y","N")))) | AF48: =IF(AB48="","",SUM(H48:K48)) | AG48: =IF(AB48="","",IF(M48<>0,(I48*0.5+L48)/M48,1)) | AK48: =IF(AB48="","",AI48*AJ48/8) | BW48: z
B49: =IF(AD49="","",IF(ISERROR(FIND(CHAR(10),AD49,1)),AD49,LEFT(AD49,FIND(CHAR(10),AD49,1)))) | C49: =IF(AD49="","",IFERROR(RIGHT(AD49,LEN(AD49)-FIND("@@@",SUBSTITUTE(AD49,CHAR(10),"@@@",LEN(AD49)-LEN(SUBSTITUTE(AD49,CHAR(10),""))),1)),AD49)) | D49: =IFERROR(DATE(("20"&MID(B49,7,2))*1,MID(B49,4,2)*1,MID(B49,1,2)*1),"") | E49: =IFERROR(DATE(("20"&MID(C49,7,2))*1,MID(C49,4,2)*1,MID(C49,1,2)*1),"") | F49: =MAX(D49,IF(E49="none",D49,E49)) -> 0 | G49: =IFERROR(DAYS360(D49,F49),0) -> 0 | H49: =((LEN($AE49)-LEN(SUBSTITUTE($AE49,CHAR(10)&". ","")))/3)+IF(LEFT(TRIM($AE49),2)=". ",1,0) -> 0 | I49: =((LEN($AE49)-LEN(SUBSTITUTE($AE49,CHAR(10)&"/ ","")))/3)+IF(LEFT(TRIM($AE49),2)="/ ",1,0) -> 0 | J49: =((LEN($AE49)-LEN(SUBSTITUTE($AE49,CHAR(10)&"~ ","")))/3)+IF(LEFT(TRIM($AE49),2)="~ ",1,0) -> 0 | K49: =((LEN($AE49)-LEN(SUBSTITUTE($AE49,CHAR(10)&"! ","")))/3)+IF(LEFT(TRIM($AE49),2)="! ",1,0) -> 0 | L49: =((LEN($AE49)-LEN(SUBSTITUTE($AE49,CHAR(10)&"x ","")))/3)+IF(LEFT(TRIM($AE49),2)="x ",1,0) -> 0 | M49: =SUM(H49:L49) -> 0 | N49: =IF(F49>(($A$21-WEEKDAY($A$21,2))-7*$F$22),"Y","N") -> N | O49: =IF(AB49=""," - ZZZ"," - "&X49&Y49&AB49) -> - ZZZ | P49: =IF(AB49="","",(IF(OR(Q49="Y",Q49="N"),Q49,IF(N49="Y","Y","N")))) | AF49: =IF(AB49="","",SUM(H49:K49)) | AG49: =IF(AB49="","",IF(M49<>0,(I49*0.5+L49)/M49,1)) | AK49: =IF(AB49="","",AI49*AJ49/8) | BW49: z
B50: =IF(AD50="","",IF(ISERROR(FIND(CHAR(10),AD50,1)),AD50,LEFT(AD50,FIND(CHAR(10),AD50,1)))) | C50: =IF(AD50="","",IFERROR(RIGHT(AD50,LEN(AD50)-FIND("@@@",SUBSTITUTE(AD50,CHAR(10),"@@@",LEN(AD50)-LEN(SUBSTITUTE(AD50,CHAR(10),""))),1)),AD50)) | D50: =IFERROR(DATE(("20"&MID(B50,7,2))*1,MID(B50,4,2)*1,MID(B50,1,2)*1),"") | E50: =IFERROR(DATE(("20"&MID(C50,7,2))*1,MID(C50,4,2)*1,MID(C50,1,2)*1),"") | F50: =MAX(D50,IF(E50="none",D50,E50)) -> 0 | G50: =IFERROR(DAYS360(D50,F50),0) -> 0 | H50: =((LEN($AE50)-LEN(SUBSTITUTE($AE50,CHAR(10)&". ","")))/3)+IF(LEFT(TRIM($AE50),2)=". ",1,0) -> 0 | I50: =((LEN($AE50)-LEN(SUBSTITUTE($AE50,CHAR(10)&"/ ","")))/3)+IF(LEFT(TRIM($AE50),2)="/ ",1,0) -> 0 | J50: =((LEN($AE50)-LEN(SUBSTITUTE($AE50,CHAR(10)&"~ ","")))/3)+IF(LEFT(TRIM($AE50),2)="~ ",1,0) -> 0 | K50: =((LEN($AE50)-LEN(SUBSTITUTE($AE50,CHAR(10)&"! ","")))/3)+IF(LEFT(TRIM($AE50),2)="! ",1,0) -> 0 | L50: =((LEN($AE50)-LEN(SUBSTITUTE($AE50,CHAR(10)&"x ","")))/3)+IF(LEFT(TRIM($AE50),2)="x ",1,0) -> 0 | M50: =SUM(H50:L50) -> 0 | N50: =IF(F50>(($A$21-WEEKDAY($A$21,2))-7*$F$22),"Y","N") -> N | O50: =IF(AB50=""," - ZZZ"," - "&X50&Y50&AB50) -> - ZZZ | P50: =IF(AB50="","",(IF(OR(Q50="Y",Q50="N"),Q50,IF(N50="Y","Y","N")))) | AF50: =IF(AB50="","",SUM(H50:K50)) | AG50: =IF(AB50="","",IF(M50<>0,(I50*0.5+L50)/M50,1)) | AK50: =IF(AB50="","",AI50*AJ50/8) | BW50: z
B51: =IF(AD51="","",IF(ISERROR(FIND(CHAR(10),AD51,1)),AD51,LEFT(AD51,FIND(CHAR(10),AD51,1)))) | C51: =IF(AD51="","",IFERROR(RIGHT(AD51,LEN(AD51)-FIND("@@@",SUBSTITUTE(AD51,CHAR(10),"@@@",LEN(AD51)-LEN(SUBSTITUTE(AD51,CHAR(10),""))),1)),AD51)) | D51: =IFERROR(DATE(("20"&MID(B51,7,2))*1,MID(B51,4,2)*1,MID(B51,1,2)*1),"") | E51: =IFERROR(DATE(("20"&MID(C51,7,2))*1,MID(C51,4,2)*1,MID(C51,1,2)*1),"") | F51: =MAX(D51,IF(E51="none",D51,E51)) -> 0 | G51: =IFERROR(DAYS360(D51,F51),0) -> 0 | H51: =((LEN($AE51)-LEN(SUBSTITUTE($AE51,CHAR(10)&". ","")))/3)+IF(LEFT(TRIM($AE51),2)=". ",1,0) -> 0 | I51: =((LEN($AE51)-LEN(SUBSTITUTE($AE51,CHAR(10)&"/ ","")))/3)+IF(LEFT(TRIM($AE51),2)="/ ",1,0) -> 0 | J51: =((LEN($AE51)-LEN(SUBSTITUTE($AE51,CHAR(10)&"~ ","")))/3)+IF(LEFT(TRIM($AE51),2)="~ ",1,0) -> 0 | K51: =((LEN($AE51)-LEN(SUBSTITUTE($AE51,CHAR(10)&"! ","")))/3)+IF(LEFT(TRIM($AE51),2)="! ",1,0) -> 0 | L51: =((LEN($AE51)-LEN(SUBSTITUTE($AE51,CHAR(10)&"x ","")))/3)+IF(LEFT(TRIM($AE51),2)="x ",1,0) -> 0 | M51: =SUM(H51:L51) -> 0 | N51: =IF(F51>(($A$21-WEEKDAY($A$21,2))-7*$F$22),"Y","N") -> N | O51: =IF(AB51=""," - ZZZ"," - "&X51&Y51&AB51) -> - ZZZ | P51: =IF(AB51="","",(IF(OR(Q51="Y",Q51="N"),Q51,IF(N51="Y","Y","N")))) | AF51: =IF(AB51="","",SUM(H51:K51)) | AG51: =IF(AB51="","",IF(M51<>0,(I51*0.5+L51)/M51,1)) | AK51: =IF(AB51="","",AI51*AJ51/8) | BW51: z
B52: =IF(AD52="","",IF(ISERROR(FIND(CHAR(10),AD52,1)),AD52,LEFT(AD52,FIND(CHAR(10),AD52,1)))) | C52: =IF(AD52="","",IFERROR(RIGHT(AD52,LEN(AD52)-FIND("@@@",SUBSTITUTE(AD52,CHAR(10),"@@@",LEN(AD52)-LEN(SUBSTITUTE(AD52,CHAR(10),""))),1)),AD52)) | D52: =IFERROR(DATE(("20"&MID(B52,7,2))*1,MID(B52,4,2)*1,MID(B52,1,2)*1),"") | E52: =IFERROR(DATE(("20"&MID(C52,7,2))*1,MID(C52,4,2)*1,MID(C52,1,2)*1),"") | F52: =MAX(D52,IF(E52="none",D52,E52)) -> 0 | G52: =IFERROR(DAYS360(D52,F52),0) -> 0 | H52: =((LEN($AE52)-LEN(SUBSTITUTE($AE52,CHAR(10)&". ","")))/3)+IF(LEFT(TRIM($AE52),2)=". ",1,0) -> 0 | I52: =((LEN($AE52)-LEN(SUBSTITUTE($AE52,CHAR(10)&"/ ","")))/3)+IF(LEFT(TRIM($AE52),2)="/ ",1,0) -> 0 | J52: =((LEN($AE52)-LEN(SUBSTITUTE($AE52,CHAR(10)&"~ ","")))/3)+IF(LEFT(TRIM($AE52),2)="~ ",1,0) -> 0 | K52: =((LEN($AE52)-LEN(SUBSTITUTE($AE52,CHAR(10)&"! ","")))/3)+IF(LEFT(TRIM($AE52),2)="! ",1,0) -> 0 | L52: =((LEN($AE52)-LEN(SUBSTITUTE($AE52,CHAR(10)&"x ","")))/3)+IF(LEFT(TRIM($AE52),2)="x ",1,0) -> 0 | M52: =SUM(H52:L52) -> 0 | N52: =IF(F52>(($A$21-WEEKDAY($A$21,2))-7*$F$22),"Y","N") -> N | O52: =IF(AB52=""," - ZZZ"," - "&X52&Y52&AB52) -> - ZZZ | P52: =IF(AB52="","",(IF(OR(Q52="Y",Q52="N"),Q52,IF(N52="Y","Y","N")))) | AF52: =IF(AB52="","",SUM(H52:K52)) | AG52: =IF(AB52="","",IF(M52<>0,(I52*0.5+L52)/M52,1)) | AK52: =IF(AB52="","",AI52*AJ52/8) | BW52: z
B53: =IF(AD53="","",IF(ISERROR(FIND(CHAR(10),AD53,1)),AD53,LEFT(AD53,FIND(CHAR(10),AD53,1)))) | C53: =IF(AD53="","",IFERROR(RIGHT(AD53,LEN(AD53)-FIND("@@@",SUBSTITUTE(AD53,CHAR(10),"@@@",LEN(AD53)-LEN(SUBSTITUTE(AD53,CHAR(10),""))),1)),AD53)) | D53: =IFERROR(DATE(("20"&MID(B53,7,2))*1,MID(B53,4,2)*1,MID(B53,1,2)*1),"") | E53: =IFERROR(DATE(("20"&MID(C53,7,2))*1,MID(C53,4,2)*1,MID(C53,1,2)*1),"") | F53: =MAX(D53,IF(E53="none",D53,E53)) -> 0 | G53: =IFERROR(DAYS360(D53,F53),0) -> 0 | H53: =((LEN($AE53)-LEN(SUBSTITUTE($AE53,CHAR(10)&". ","")))/3)+IF(LEFT(TRIM($AE53),2)=". ",1,0) -> 0 | I53: =((LEN($AE53)-LEN(SUBSTITUTE($AE53,CHAR(10)&"/ ","")))/3)+IF(LEFT(TRIM($AE53),2)="/ ",1,0) -> 0 | J53: =((LEN($AE53)-LEN(SUBSTITUTE($AE53,CHAR(10)&"~ ","")))/3)+IF(LEFT(TRIM($AE53),2)="~ ",1,0) -> 0 | K53: =((LEN($AE53)-LEN(SUBSTITUTE($AE53,CHAR(10)&"! ","")))/3)+IF(LEFT(TRIM($AE53),2)="! ",1,0) -> 0 | L53: =((LEN($AE53)-LEN(SUBSTITUTE($AE53,CHAR(10)&"x ","")))/3)+IF(LEFT(TRIM($AE53),2)="x ",1,0) -> 0 | M53: =SUM(H53:L53) -> 0 | N53: =IF(F53>(($A$21-WEEKDAY($A$21,2))-7*$F$22),"Y","N") -> N | O53: =IF(AB53=""," - ZZZ"," - "&X53&Y53&AB53) -> - ZZZ | P53: =IF(AB53="","",(IF(OR(Q53="Y",Q53="N"),Q53,IF(N53="Y","Y","N")))) | AF53: =IF(AB53="","",SUM(H53:K53)) | AG53: =IF(AB53="","",IF(M53<>0,(I53*0.5+L53)/M53,1)) | AK53: =IF(AB53="","",AI53*AJ53/8) | BW53: z
...

Sheet GTD
D1: Select GTD Type from drop-down list. | E1: Type Project Name, Routine Name, Reference Name | F1: Type Task Name (=Name of reportable item for a Reference) | G1: Type “Self” for Taks owned by self. Type name of someone else in all other cases (if someone is Owner) | H1: Expected Date of Completion | I1: Actual Completion Date | J1: Date at which the Reference Item should be Reported. | K1: Provide details. No specific format. | L1: GTD List as per [Management Framework ## GTD] | M1: Additional List in case of Projects, Routines and References. If OneNote is available, each is represented by a Section and in it there is a page with the Project Name, Routine Name and Reference Name as per Collumn “Project / Routine / Reference Name” - Project Details - Project Name 1 - etc - Routine Details - Routine Name 1 - etc - Reference Details - Reference Name 1 - etc | N1: Indication how close the Due Date is: - Overdue - Due in 7 days - Due in 30 days | O1: Whether an item is reportable based on Done Date or Tickle Date | P1: Integrity Checls of each Row | Q1: Last Column. Contains value = “X”.
A2: =TODAY() -> 46321 | B2: 1 | D2: Manual | E2: Manual | F2: Manual | G2: Manual | H2: Manual | I2: Manual | J2: Manual | K2: Manual | L2: Calculated | M2: Calculated | N2: Calculated | O2: Calculated | P2: Calculated
A3: A | C3: Sort | D3: GTD Type | E3: Project / Routine / Reference Name | F3: Task Name | G3: Owner | H3: Due Date | I3: Done Date | J3: Tickle Date | K3: Details | L3: List | M3: Additional List | N3: Overdue / Due 7d / Due 30d | O3: Report | P3: Check | Q3: Z
A4: =A3 -> A | C4: =C3 -> Sort | D4: =D3 -> GTD Type | E4: =E3 -> Project / Routine / Reference Name | F4: =F3 -> Task Name | G4: =G3 -> Owner | H4: =H3 -> Due Date | I4: =I3 -> Done Date | J4: =J3 -> Tickle Date | ... Q4: =Q3 -> Z
C5: =IF( D5=""," - ZZZ", " - "&F5&E5&F5) -> - Project 1 | D5: Project | E5: Project 1 | G5: Self | H5: 44209 | I5: 46288 | K5: Details: | L5: =IF( I5<>"","Delete", IF( AND(G5="Self",H5<>""),"Defer", IF( AND(G5<>"",G5<>"Self",H5<>""),"Delegate", IF( D5="Project","Projects", IF( D5="Routine","Routines", IF( D5="Task","Someday", IF( D5="Reference","Reference", "" ) ) ) ) ) ) ) -> Delete | M5: =IF( D5="Project","Project Details", IF( D5="Routine","Routine Details", IF( D5="Reference","Reference Details", "" ) ) ) -> Project Details | N5: =IF( D5="","", IF( AND(H5<>"",I5="",H5<$A$2),"Overdue", IF( AND(H5<>"",I5="",(7*1+$A$2)>H5),"Due 7d", IF( AND(H5<>"",I5="",(30*1+$A$2)>H5),"Due 30d", "None" ) ) ) ) -> None | O5: =IF( D5="","", IF( I5>($A$2-7*$B$2),"Yes", IF( J5>($A$2-7*$B$2),"Yes", "No" ) ) ) -> No | P5: =IF( D5="","", IF( AND(H5<>"",G5=""),"Error: no Owner for Task with Due Date", "ok" ) ) -> ok | Q5: z
